try {
    throw("test", "TestError")
} catch (e) {
    if e == "TestError" {
        output("Caught TestError")
    }
}